{"uuid": "a7ad06ba-dc71-4ded-8fc4-04c8cc212a1d", "children": ["a1403255-d373-4b6b-a163-d72f389cbf8a"], "befores": [{"name": "login1", "status": "failed", "statusDetails": {"message": "Failed: Fixture \"login\" called directly. Fixtures are not meant to be called directly,\nbut are created automatically when test functions request them as parameters.\nSee https://docs.pytest.org/en/stable/fixture.html for more information about fixtures, and\nhttps://docs.pytest.org/en/stable/deprecations.html#calling-fixtures-directly about how to update your code.\n", "trace": "  File \"D:\\Users\\tn_chenghao.yan\\AppData\\Local\\Programs\\Python\\Python39\\lib\\site-packages\\pluggy\\_callers.py\", line 39, in _multicall\n    res = hook_impl.function(*args)\n  File \"D:\\Users\\tn_chenghao.yan\\AppData\\Local\\Programs\\Python\\Python39\\lib\\site-packages\\_pytest\\fixtures.py\", line 1126, in pytest_fixture_setup\n    result = call_fixture_func(fixturefunc, request, kwargs)\n  File \"D:\\Users\\tn_chenghao.yan\\AppData\\Local\\Programs\\Python\\Python39\\lib\\site-packages\\_pytest\\fixtures.py\", line 925, in call_fixture_func\n    fixture_result = next(generator)\n  File \"C:\\Users\\tn_chenghao.yan\\PycharmProjects\\pythonProject\\test_request\\testcase\\conftest.py\", line 51, in login1\n    login()\n  File \"D:\\Users\\tn_chenghao.yan\\AppData\\Local\\Programs\\Python\\Python39\\lib\\site-packages\\_pytest\\fixtures.py\", line 1176, in result\n    fail(message, pytrace=False)\n  File \"D:\\Users\\tn_chenghao.yan\\AppData\\Local\\Programs\\Python\\Python39\\lib\\site-packages\\_pytest\\outcomes.py\", line 153, in fail\n    raise Failed(msg=msg, pytrace=pytrace)\n"}, "start": 1640754196961, "stop": 1640754196961}], "start": 1640754196961, "stop": 1640754196992}