{"uuid": "20445963-f55c-4c88-b815-3e41674bb736", "children": ["b414d13d-9e0d-4f7e-9440-366d12df2a7f"], "befores": [{"name": "login1", "status": "failed", "statusDetails": {"message": "Failed: Fixture \"login\" called directly. Fixtures are not meant to be called directly,\nbut are created automatically when test functions request them as parameters.\nSee https://docs.pytest.org/en/stable/fixture.html for more information about fixtures, and\nhttps://docs.pytest.org/en/stable/deprecations.html#calling-fixtures-directly about how to update your code.\n", "trace": "  File \"D:\\Users\\tn_chenghao.yan\\AppData\\Local\\Programs\\Python\\Python39\\lib\\site-packages\\pluggy\\_callers.py\", line 39, in _multicall\n    res = hook_impl.function(*args)\n  File \"D:\\Users\\tn_chenghao.yan\\AppData\\Local\\Programs\\Python\\Python39\\lib\\site-packages\\_pytest\\fixtures.py\", line 1126, in pytest_fixture_setup\n    result = call_fixture_func(fixturefunc, request, kwargs)\n  File \"D:\\Users\\tn_chenghao.yan\\AppData\\Local\\Programs\\Python\\Python39\\lib\\site-packages\\_pytest\\fixtures.py\", line 925, in call_fixture_func\n    fixture_result = next(generator)\n  File \"C:\\Users\\tn_chenghao.yan\\PycharmProjects\\pythonProject\\test_request\\testcase\\conftest.py\", line 51, in login1\n    login()\n  File \"D:\\Users\\tn_chenghao.yan\\AppData\\Local\\Programs\\Python\\Python39\\lib\\site-packages\\_pytest\\fixtures.py\", line 1176, in result\n    fail(message, pytrace=False)\n  File \"D:\\Users\\tn_chenghao.yan\\AppData\\Local\\Programs\\Python\\Python39\\lib\\site-packages\\_pytest\\outcomes.py\", line 153, in fail\n    raise Failed(msg=msg, pytrace=pytrace)\n"}, "start": 1640754573397, "stop": 1640754573398}], "start": 1640754573397, "stop": 1640754573438}