{"uuid": "58f90809-2476-40e4-99ca-d6cafeb28b03", "children": ["7d71f054-1748-400d-af34-79de5267b656"], "befores": [{"name": "login", "status": "broken", "statusDetails": {"message": "requests.exceptions.ConnectionError: HTTPSConnectionPool(host='api.molelive.com', port=443): Max retries exceeded with url: /api/user/snackUser/login (Caused by NewConnectionError('<urllib3.connection.HTTPSConnection object at 0x000001EC454027F0>: Failed to establish a new connection: [Errno 11001] getaddrinfo failed'))\n", "trace": "  File \"D:\\Users\\tn_chenghao.yan\\AppData\\Local\\Programs\\Python\\Python39\\lib\\site-packages\\pluggy\\_callers.py\", line 39, in _multicall\n    res = hook_impl.function(*args)\n  File \"D:\\Users\\tn_chenghao.yan\\AppData\\Local\\Programs\\Python\\Python39\\lib\\site-packages\\_pytest\\fixtures.py\", line 1126, in pytest_fixture_setup\n    result = call_fixture_func(fixturefunc, request, kwargs)\n  File \"D:\\Users\\tn_chenghao.yan\\AppData\\Local\\Programs\\Python\\Python39\\lib\\site-packages\\_pytest\\fixtures.py\", line 932, in call_fixture_func\n    fixture_result = fixturefunc(**kwargs)\n  File \"C:\\Users\\tn_chenghao.yan\\PycharmProjects\\pythonProject\\test_request\\testcase\\test_popular.py\", line 39, in login\n    r1=request1.request(url1,headers=header,json=params,http_method=\"post\",timeout=5,verify=False)\n  File \"C:\\Users\\tn_chenghao.yan\\PycharmProjects\\pythonProject\\test_request\\common\\http_requests.py\", line 9, in request\n    red = requests.post(url,headers=headers,data=data,json=json,timeout=timeout,verify=verify,cookies=cookie)\n  File \"D:\\Users\\tn_chenghao.yan\\AppData\\Local\\Programs\\Python\\Python39\\lib\\site-packages\\requests\\api.py\", line 117, in post\n    return request('post', url, data=data, json=json, **kwargs)\n  File \"D:\\Users\\tn_chenghao.yan\\AppData\\Local\\Programs\\Python\\Python39\\lib\\site-packages\\requests\\api.py\", line 61, in request\n    return session.request(method=method, url=url, **kwargs)\n  File \"D:\\Users\\tn_chenghao.yan\\AppData\\Local\\Programs\\Python\\Python39\\lib\\site-packages\\requests\\sessions.py\", line 542, in request\n    resp = self.send(prep, **send_kwargs)\n  File \"D:\\Users\\tn_chenghao.yan\\AppData\\Local\\Programs\\Python\\Python39\\lib\\site-packages\\requests\\sessions.py\", line 655, in send\n    r = adapter.send(request, **kwargs)\n  File \"D:\\Users\\tn_chenghao.yan\\AppData\\Local\\Programs\\Python\\Python39\\lib\\site-packages\\requests\\adapters.py\", line 516, in send\n    raise ConnectionError(e, request=request)\n"}, "start": 1639750050559, "stop": 1639750050570}], "start": 1639750050559, "stop": 1639750050770}